Workbook
Name k_bedroom: Cooling_Calc!$E$3
Name k_kitchen: Cooling_Calc!$E$4
Name k_printernya: Cooling_Calc!$E$5
Name Porig: Cooling_Calc!$C$7
Name T_vul: Cooling_Calc!$C$6
Name T0: Cooling_Calc!$C$5
Name Роздільник_Місяць: #N/A

Sheet Data
A1: Дата-час (Київ) | B1: Місяць | C1: Година | D1: Кімната °C | E1: Кухня °C | F1: Кладова °C | G1: Надворі °C | H1: Кімната RH | I1: Кухня RH | J1: Кладова RH | K1: Надворі RH
A2: 46097.417 | B2: =TEXT(A2,"yyyy-mm") -> 2026-03 | C2: =HOUR(A2) -> 10 | D2: 23.750845 | G2: 5.7 | H2: 28.133015 | K2: 69
A3: 46097.458 | B3: =TEXT(A3,"yyyy-mm") -> 2026-03 | C3: =HOUR(A3) -> 11 | D3: 24.797228 | G3: 7.3 | H3: 28.307501 | K3: 62
A4: 46097.5 | B4: =TEXT(A4,"yyyy-mm") -> 2026-03 | C4: =HOUR(A4) -> 12 | D4: 23.036917 | G4: 8.3 | H4: 27.546536 | K4: 57
A5: 46097.542 | B5: =TEXT(A5,"yyyy-mm") -> 2026-03 | C5: =HOUR(A5) -> 13 | D5: 23.588672 | G5: 8 | H5: 26.783216 | K5: 60
A6: 46097.583 | B6: =TEXT(A6,"yyyy-mm") -> 2026-03 | C6: =HOUR(A6) -> 14 | D6: 24.664111 | G6: 9.1 | H6: 27.831592 | K6: 54
A7: 46097.625 | B7: =TEXT(A7,"yyyy-mm") -> 2026-03 | C7: =HOUR(A7) -> 15 | D7: 24.741414 | G7: 9.2 | H7: 28.363218 | K7: 51
A8: 46097.667 | B8: =TEXT(A8,"yyyy-mm") -> 2026-03 | C8: =HOUR(A8) -> 16 | D8: 24.487313 | G8: 8.6 | H8: 29.403072 | K8: 56
A9: 46097.708 | B9: =TEXT(A9,"yyyy-mm") -> 2026-03 | C9: =HOUR(A9) -> 17 | D9: 24.55347 | G9: 7.5 | H9: 31.45372 | K9: 62
A10: 46097.75 | B10: =TEXT(A10,"yyyy-mm") -> 2026-03 | C10: =HOUR(A10) -> 18 | D10: 24.566719 | G10: 6.4 | H10: 31.749659 | K10: 67
A11: 46097.792 | B11: =TEXT(A11,"yyyy-mm") -> 2026-03 | C11: =HOUR(A11) -> 19 | D11: 24.409221 | G11: 5.5 | H11: 32.094126 | K11: 71
A12: 46097.833 | B12: =TEXT(A12,"yyyy-mm") -> 2026-03 | C12: =HOUR(A12) -> 20 | D12: 24.355717 | G12: 5.3 | H12: 34.981259 | K12: 77
A13: 46097.875 | B13: =TEXT(A13,"yyyy-mm") -> 2026-03 | C13: =HOUR(A13) -> 21 | D13: 24.282015 | G13: 4.5 | H13: 37.283803 | K13: 80
... A42: 46099.083 | B42: =TEXT(A42,"yyyy-mm") -> 2026-03 | C42: =HOUR(A42) -> 2 | D42: 23.208396 | G42: 2.2 | H42: 36.767468 | K42: 98
A43: 46099.125 | B43: =TEXT(A43,"yyyy-mm") -> 2026-03 | C43: =HOUR(A43) -> 3 | G43: 2.3 | K43: 98
A44: 46099.167 | B44: =TEXT(A44,"yyyy-mm") -> 2026-03 | C44: =HOUR(A44) -> 4 | G44: 2.1 | K44: 98
A45: 46099.208 | B45: =TEXT(A45,"yyyy-mm") -> 2026-03 | C45: =HOUR(A45) -> 5 | G45: 1.8 | K45: 99
A46: 46099.25 | B46: =TEXT(A46,"yyyy-mm") -> 2026-03 | C46: =HOUR(A46) -> 6 | G46: 1.6 | K46: 99
A47: 46099.292 | B47: =TEXT(A47,"yyyy-mm") -> 2026-03 | C47: =HOUR(A47) -> 7 | G47: 2.1 | K47: 96
A48: 46099.333 | B48: =TEXT(A48,"yyyy-mm") -> 2026-03 | C48: =HOUR(A48) -> 8 | G48: 3 | K48: 93
A49: 46099.375 | B49: =TEXT(A49,"yyyy-mm") -> 2026-03 | C49: =HOUR(A49) -> 9 | D49: 22.843813 | G49: 3.8 | H49: 38.335718 | K49: 89
A50: 46099.417 | B50: =TEXT(A50,"yyyy-mm") -> 2026-03 | C50: =HOUR(A50) -> 10 | D50: 22.797096 | G50: 4.2 | H50: 37.241255 | K50: 88
A51: 46099.458 | B51: =TEXT(A51,"yyyy-mm") -> 2026-03 | C51: =HOUR(A51) -> 11 | D51: 23.265929 | G51: 4.4 | H51: 36.517486 | K51: 87
A52: 46099.5 | B52: =TEXT(A52,"yyyy-mm") -> 2026-03 | C52: =HOUR(A52) -> 12 | D52: 23.505711 | G52: 4.9 | H52: 35.934936 | K52: 86
A53: 46099.542 | B53: =TEXT(A53,"yyyy-mm") -> 2026-03 | C53: =HOUR(A53) -> 13 | D53: 23.23941 | G53: 5.1 | H53: 35.07686 | K53: 84
A54: 46099.583 | B54: =TEXT(A54,"yyyy-mm") -> 2026-03 | C54: =HOUR(A54) -> 14 | D54: 23.237603 | G54: 5.3 | H54: 34.222992 | K54: 83
A55: 46099.625 | B55: =TEXT(A55,"yyyy-mm") -> 2026-03 | C55: =HOUR(A55) -> 15 | D55: 23.353401 | G55: 5.2 | H55: 33.815904 | K55: 82
A56: 46099.667 | B56: =TEXT(A56,"yyyy-mm") -> 2026-03 | C56: =HOUR(A56) -> 16 | D56: 23.272135 | G56: 5.1 | H56: 34.678931 | K56: 82
A57: 46099.708 | B57: =TEXT(A57,"yyyy-mm") -> 2026-03 | C57: =HOUR(A57) -> 17 | D57: 23.075593 | G57: 4.6 | H57: 35.603569 | K57: 85
A58: 46099.75 | B58: =TEXT(A58,"yyyy-mm") -> 2026-03 | C58: =HOUR(A58) -> 18 | D58: 23.123044 | G58: 3.8 | H58: 38.0809 | K58: 89
A59: 46099.792 | B59: =TEXT(A59,"yyyy-mm") -> 2026-03 | C59: =HOUR(A59) -> 19 | D59: 23.189253 | G59: 3.1 | H59: 39.172661 | K59: 93
A60: 46099.833 | B60: =TEXT(A60,"yyyy-mm") -> 2026-03 | C60: =HOUR(A60) -> 20 | D60: 23.294817 | G60: 3.5 | H60: 41.058827 | K60: 96
... A461: 46116.583 | B461: =TEXT(A461,"yyyy-mm") -> 2026-04 | C461: =HOUR(A461) -> 14 | D461: 24.445121 | G461: 16.6 | H461: 41.043966 | K461: 63
A462: 46116.625 | B462: =TEXT(A462,"yyyy-mm") -> 2026-04 | C462: =HOUR(A462) -> 15 | D462: 24.436721 | E462: 25.587984 | G462: 14.2 | H462: 42.658612 | I462: 40.943839 | K462: 78
A463: 46116.667 | B463: =TEXT(A463,"yyyy-mm") -> 2026-04 | C463: =HOUR(A463) -> 16 | D463: 24.193552 | E463: 25.410361 | G463: 14.2 | H463: 45.109583 | I463: 42.045472 | K463: 73
A464: 46116.708 | B464: =TEXT(A464,"yyyy-mm") -> 2026-04 | C464: =HOUR(A464) -> 17 | D464: 23.775956 | G464: 15.1 | H464: 45.177889 | K464: 65
A465: 46116.75 | B465: =TEXT(A465,"yyyy-mm") -> 2026-04 | C465: =HOUR(A465) -> 18 | D465: 23.25712 | E465: 25.252454 | G465: 14.5 | H465: 44.058058 | I465: 40.35645 | K465: 72
A466: 46116.792 | B466: =TEXT(A466,"yyyy-mm") -> 2026-04 | C466: =HOUR(A466) -> 19 | D466: 22.958649 | E466: 24.643176 | F466: 24.540415 | G466: 12.8 | H466: 44.024789 | I466: 44.915055 | J466: 56.121925 | K466: 75
A467: 46116.833 | B467: =TEXT(A467,"yyyy-mm") -> 2026-04 | C467: =HOUR(A467) -> 20 | D467: 22.237798 | E467: 24.332275 | F467: 24.650355 | G467: 11.4 | H467: 44.165606 | I467: 43.834496 | J467: 54.564765 | K467: 80
A468: 46116.875 | B468: =TEXT(A468,"yyyy-mm") -> 2026-04 | C468: =HOUR(A468) -> 21 | D468: 21.982704 | E468: 24.131826 | F468: 24.801271 | G468: 10.9 | H468: 44.551442 | I468: 44.389739 | J468: 52.758325 | K468: 86
...

Sheet Blackout_Log
A1: № | B1: Початок (Київ) | C1: Кінець (Київ) | D1: Тривалість год | E1: День тижня | F1: Місяць | G1: Джерело | H1: Примітка | J1: Зведення по відключеннях
A2: 1 | B2: 46099.125 | C2: 46099.375 | D2: 6 | E2: =TEXT(B2,"dddd") -> середа | F2: =TEXT(B2,"yyyy-mm") -> 2026-03 | G2: погодинні | H2: мовчать усі доступні розеткові датчики (1): bedroom_temp; НИЗЬКА ВПЕВНЕНІСТЬ: у той час працював лише один розетковий датчик | J2: Кількість відключень | K2: =COUNTA(A2:A6) -> 5
A3: 2 | B3: 46186.458 | C3: 46186.792 | D3: 8 | E3: =TEXT(B3,"dddd") -> субота | F3: =TEXT(B3,"yyyy-mm") -> 2026-06 | G3: погодинні | H3: мовчать усі доступні розеткові датчики (4): bedroom_temp, printernya_temp, server_cpu_load, nas_sda_temp | J3: Сума годин без світла | K3: =SUM(D2:D6) -> 35
A4: 3 | B4: 46214.5 | C4: 46214.708 | D4: 5 | E4: =TEXT(B4,"dddd") -> субота | F4: =TEXT(B4,"yyyy-mm") -> 2026-07 | G4: погодинні | H4: мовчать усі доступні розеткові датчики (4): bedroom_temp, printernya_temp, server_cpu_load, nas_sda_temp; квітка теж мовчала → сервер був вимкнений | J4: Медіана тривалості, год | K4: =MEDIAN(D2:D6) -> 7
A5: 4 | B5: 46215.458 | C5: 46215.75 | D5: 7 | E5: =TEXT(B5,"dddd") -> неділя | F5: =TEXT(B5,"yyyy-mm") -> 2026-07 | G5: погодинні | H5: мовчать усі доступні розеткові датчики (4): bedroom_temp, printernya_temp, server_cpu_load, nas_sda_temp; квітка теж мовчала → сервер був вимкнений | J5: Максимум, год | K5: =MAX(D2:D6) -> 9
A6: 5 | B6: 46228.458 | C6: 46228.833 | D6: 9 | E6: =TEXT(B6,"dddd") -> субота | F6: =TEXT(B6,"yyyy-mm") -> 2026-07 | G6: погодинні | H6: мовчать усі доступні розеткові датчики (4): bedroom_temp, printernya_temp, server_cpu_load, nas_sda_temp; квітка теж мовчала → сервер був вимкнений | J6: Всього годин у періоді | K6: 4402
J7: Uptime (частка часу зі світлом) | K7: =1-K3/K6 -> 0.99204907

Sheet Dashboard
A1: Dashboard — 4331 година
A4: Середня температура за місяць, °C | G4: Мінімум / максимум за період, °C
A5: Місяць | B5: Кімната | C5: Кухня | D5: Кладова | E5: Надворі | G5: Кімната | H5: Мін | I5: Макс
A6: 2026-03 | B6: =IFERROR(AVERAGEIFS(raw[Кімната °C],raw[Місяць],$A6),"") -> 22.691941 | C6: =IFERROR(AVERAGEIFS(raw[Кухня °C],raw[Місяць],$A6),"") | D6: =IFERROR(AVERAGEIFS(raw[Кладова °C],raw[Місяць],$A6),"") | E6: =IFERROR(AVERAGEIFS(raw[Надворі °C],raw[Місяць],$A6),"") -> 6.9075067 | G6: Кімната | H6: =MIN(raw[Кімната °C]) -> 19.164767 | I6: =MAX(raw[Кімната °C]) -> 30.170578
A7: 2026-04 | B7: =IFERROR(AVERAGEIFS(raw[Кімната °C],raw[Місяць],$A7),"") -> 21.954304 | C7: =IFERROR(AVERAGEIFS(raw[Кухня °C],raw[Місяць],$A7),"") -> 23.454832 | D7: =IFERROR(AVERAGEIFS(raw[Кладова °C],raw[Місяць],$A7),"") -> 23.409543 | E7: =IFERROR(AVERAGEIFS(raw[Надворі °C],raw[Місяць],$A7),"") -> 7.2530556 | G7: Кухня | H7: =MIN(raw[Кухня °C]) -> 21.697224 | I7: =MAX(raw[Кухня °C]) -> 30.361688
A8: 2026-05 | B8: =IFERROR(AVERAGEIFS(raw[Кімната °C],raw[Місяць],$A8),"") -> 24.057717 | C8: =IFERROR(AVERAGEIFS(raw[Кухня °C],raw[Місяць],$A8),"") -> 25.560903 | D8: =IFERROR(AVERAGEIFS(raw[Кладова °C],raw[Місяць],$A8),"") -> 25.578651 | E8: =IFERROR(AVERAGEIFS(raw[Надворі °C],raw[Місяць],$A8),"") -> 16.918145 | G8: Кладова | H8: =MIN(raw[Кладова °C]) -> 22.155182 | I8: =MAX(raw[Кладова °C]) -> 30.173221
A9: 2026-06 | B9: =IFERROR(AVERAGEIFS(raw[Кімната °C],raw[Місяць],$A9),"") -> 25.502107 | C9: =IFERROR(AVERAGEIFS(raw[Кухня °C],raw[Місяць],$A9),"") -> 26.992544 | D9: =IFERROR(AVERAGEIFS(raw[Кладова °C],raw[Місяць],$A9),"") -> 28.464859 | E9: =IFERROR(AVERAGEIFS(raw[Надворі °C],raw[Місяць],$A9),"") -> 20.949028 | G9: Надворі | H9: =MIN(raw[Надворі °C]) -> -1.3 | I9: =MAX(raw[Надворі °C]) -> 36.1
A10: 2026-07 | B10: =IFERROR(AVERAGEIFS(raw[Кімната °C],raw[Місяць],$A10),"") -> 25.630406 | C10: =IFERROR(AVERAGEIFS(raw[Кухня °C],raw[Місяць],$A10),"") -> 27.523685 | D10: =IFERROR(AVERAGEIFS(raw[Кладова °C],raw[Місяць],$A10),"") -> 28.77027 | E10: =IFERROR(AVERAGEIFS(raw[Надворі °C],raw[Місяць],$A10),"") -> 20.749059
A11: 2026-08 | B11: =IFERROR(AVERAGEIFS(raw[Кімната °C],raw[Місяць],$A11),"") -> 25.561817 | C11: =IFERROR(AVERAGEIFS(raw[Кухня °C],raw[Місяць],$A11),"") -> 27.84808 | D11: =IFERROR(AVERAGEIFS(raw[Кладова °C],raw[Місяць],$A11),"") -> 29.319182 | E11: =IFERROR(AVERAGEIFS(raw[Надворі °C],raw[Місяць],$A11),"") -> 23.061962 | G11: Поза комфортом 20–24°C, % часу
A12: 2026-09 | B12: =IFERROR(AVERAGEIFS(raw[Кімната °C],raw[Місяць],$A12),"") -> 24.843835 | C12: =IFERROR(AVERAGEIFS(raw[Кухня °C],raw[Місяць],$A12),"") -> 27.053649 | D12: =IFERROR(AVERAGEIFS(raw[Кладова °C],raw[Місяць],$A12),"") -> 28.585872 | E12: =IFERROR(AVERAGEIFS(raw[Надворі °C],raw[Місяць],$A12),"") -> 18.230532 | G12: Кімната | H12: % поза комфортом
G13: Кімната | H13: =(COUNTIFS(raw[Кімната °C],"<20")+COUNTIFS(raw[Кімната °C],">24"))/COUNT(raw[Кімната °C]) -> 0.58755494
A14: Години без світла за місяць | G14: Кухня | H14: =(COUNTIFS(raw[Кухня °C],"<20")+COUNTIFS(raw[Кухня °C],">24"))/COUNT(raw[Кухня °C]) -> 0.78200821
A15: Місяць | B15: Години без світла | G15: Кладова | H15: =(COUNTIFS(raw[Кладова °C],"<20")+COUNTIFS(raw[Кладова °C],">24"))/COUNT(raw[Кладова °C]) -> 0.82582345
A16: =$A6 -> 2026-03 | B16: =SUMIFS(Blackout_Log!$D$2:$D$6,Blackout_Log!$F$2:$F$6,$A16) -> 6
A17: =$A7 -> 2026-04 | B17: =SUMIFS(Blackout_Log!$D$2:$D$6,Blackout_Log!$F$2:$F$6,$A17) -> 0
A18: =$A8 -> 2026-05 | B18: =SUMIFS(Blackout_Log!$D$2:$D$6,Blackout_Log!$F$2:$F$6,$A18) -> 0
A19: =$A9 -> 2026-06 | B19: =SUMIFS(Blackout_Log!$D$2:$D$6,Blackout_Log!$F$2:$F$6,$A19) -> 8
A20: =$A10 -> 2026-07 | B20: =SUMIFS(Blackout_Log!$D$2:$D$6,Blackout_Log!$F$2:$F$6,$A20) -> 21
A21: =$A11 -> 2026-08 | B21: =SUMIFS(Blackout_Log!$D$2:$D$6,Blackout_Log!$F$2:$F$6,$A21) -> 0
A22: =$A12 -> 2026-09 | B22: =SUMIFS(Blackout_Log!$D$2:$D$6,Blackout_Log!$F$2:$F$6,$A22) -> 0
A110: Місце для зведеної таблиці та зрізу (робиться вручну, див. README)
A112: Позначки рядків | B112: Середнє з Кімната °C | C112: Середнє з Кухня °C | D112: Середнє з Кладова °C
A113: 2026-03 | B113: 22.691941
A114: 2026-04 | B114: 21.954304 | C114: 23.454832 | D114: 23.409543
A115: 2026-05 | B115: 24.057717 | C115: 25.560903 | D115: 25.578651
A116: 2026-06 | B116: 25.502107 | C116: 26.992544 | D116: 28.464859
A117: 2026-07 | B117: 25.630406 | C117: 27.523685 | D117: 28.77027
A118: 2026-08 | B118: 25.561817 | C118: 27.84808 | D118: 29.319182
A119: 2026-09 | B119: 24.843835 | C119: 27.053649 | D119: 28.585872
A120: Загальний підсумок | B120: 24.407426 | C120: 25.86658 | D120: 27.29484

Sheet Comfort
A1: Comfort — теплова карта
A3: Година | B3: Кімната | C3: Кухня | D3: Кладова | E3: Надворі
A4: 0 | B4: 23.973 | C4: 26.001 | D4: 27.306 | E4: 14.909
A5: 1 | B5: 23.699 | C5: 25.797 | D5: 27.318 | E5: 14.294
A6: 2 | B6: 23.417 | C6: 25.498 | D6: 27.331 | E6: 13.744
A7: 3 | B7: 23.23 | C7: 25.231 | D7: 27.324 | E7: 13.153
A8: 4 | B8: 23.054 | C8: 25.016 | D8: 27.313 | E8: 12.663
A9: 5 | B9: 23.086 | C9: 24.896 | D9: 27.296 | E9: 12.29
A10: 6 | B10: 23.597 | C10: 25.004 | D10: 27.286 | E10: 12.441
A11: 7 | B11: 24.254 | C11: 25.311 | D11: 27.29 | E11: 13.419
A12: 8 | B12: 24.849 | C12: 25.684 | D12: 27.311 | E12: 14.958
A13: 9 | B13: 25.211 | C13: 25.976 | D13: 27.331 | E13: 16.829
A14: 10 | B14: 25.281 | C14: 26.214 | D14: 27.351 | E14: 18.258
A15: 11 | B15: 25.238 | C15: 26.361 | D15: 27.339 | E15: 19.436
... A27: 23 | B27: 24.058 | C27: 26.01 | D27: 27.287 | E27: 15.563
A30: Комфортна температура 20–24°C за місяць, % часу
A31: Місяць | B31: Кімната | C31: Кухня | D31: Кладова
A32: 2026-03 | B32: 94.2
A33: 2026-04 | B33: 90.1 | C33: 75.6 | D33: 76.8
A34: 2026-05 | B34: 45.1 | C34: 14 | D34: 23.9
A35: 2026-06 | B35: 20.3 | C35: 1 | D35: 0
A36: 2026-07 | B36: 14.2 | C36: 0 | D36: 0
A37: 2026-08 | B37: 19 | C37: 0 | D37: 0
A38: 2026-09 | B38: 28.8 | C38: 0 | D38: 0
A40: Спарклайни (мінідіаграми в комірках) openpyxl не підтримує — можна додати вручну: виділити рядок → Вставлення → Спарклайн → Лінія.

Sheet Cooling_Calc
A1: Cooling_Calc — калькулятор охолодження квартири
D2: Кімната | E2: k, 1/год
B3: Вхідні дані | D3: Кімната | E3: 0.0034787376
B4: Кімната | C4: Кімната | D4: Кухня | E4: 0.0022148328
B5: T0, °C (у кімнаті зараз) | C5: 22 | D5: Кладова | E5: 0.0030538755
B6: T_вул, °C (надворі) | C6: -10 | D6: k з модуля M4 (метод «нічний спад», night_decay_ols)
B7: поріг, °C | C7: 18
B9: k обраної кімнати | C9: =INDEX($E$3:$E$5,MATCH(C4,$D$3:$D$5,0)) -> 0.0034787376
B10: Годин до порога | C10: =IFERROR(LN((C5-C6)/(C7-C6))/C9,"перевірте вхідні дані") -> 38.385014
B11: ="Якщо надворі "&TEXT(C6,"0")&" °C, кімната охолоне з "&TEXT(C5,"0")&" до "&TEXT(C7,"0")&" °C приблизно за "&TEXT(C10,"0,0")&" год." -> Якщо надворі -10 °C, кімната охолоне з 22 до 18 °C приблизно за 38,4 год.
B13: Примітка: k оцінено на літніх даних, довірчий інтервал широкий — уточнимо взимку.
B16: Довідкова таблиця: T_вул від −20 до +10 (T0=22, поріг=18)
B17: T0 (довідка) | C17: 22 | D17: поріг (довідка) | E17: 18
A19: T_вул, °C | B19: Кімната, год | C19: Кухня, год | D19: Кладова, год
A20: -20 | B20: =IFERROR(LN(($C$17-$A20)/($E$17-$A20))/k_bedroom,"") -> 28.770051 | C20: =IFERROR(LN(($C$17-$A20)/($E$17-$A20))/k_kitchen,"") -> 45.187816 | D20: =IFERROR(LN(($C$17-$A20)/($E$17-$A20))/k_printernya,"") -> 32.772606
A21: -15 | B21: =IFERROR(LN(($C$17-$A21)/($E$17-$A21))/k_bedroom,"") -> 32.888468 | C21: =IFERROR(LN(($C$17-$A21)/($E$17-$A21))/k_kitchen,"") -> 51.656428 | D21: =IFERROR(LN(($C$17-$A21)/($E$17-$A21))/k_printernya,"") -> 37.463986
A22: -10 | B22: =IFERROR(LN(($C$17-$A22)/($E$17-$A22))/k_bedroom,"") -> 38.385014 | C22: =IFERROR(LN(($C$17-$A22)/($E$17-$A22))/k_kitchen,"") -> 60.289604 | D22: =IFERROR(LN(($C$17-$A22)/($E$17-$A22))/k_printernya,"") -> 43.725224
A23: -5 | B23: =IFERROR(LN(($C$17-$A23)/($E$17-$A23))/k_bedroom,"") -> 46.092194 | C23: =IFERROR(LN(($C$17-$A23)/($E$17-$A23))/k_kitchen,"") -> 72.394922 | D23: =IFERROR(LN(($C$17-$A23)/($E$17-$A23))/k_printernya,"") -> 52.504645
A24: 0 | B24: =IFERROR(LN(($C$17-$A24)/($E$17-$A24))/k_bedroom,"") -> 57.684918 | C24: =IFERROR(LN(($C$17-$A24)/($E$17-$A24))/k_kitchen,"") -> 90.603089 | D24: =IFERROR(LN(($C$17-$A24)/($E$17-$A24))/k_printernya,"") -> 65.710175
A25: 5 | B25: =IFERROR(LN(($C$17-$A25)/($E$17-$A25))/k_bedroom,"") -> 77.115326 | C25: =IFERROR(LN(($C$17-$A25)/($E$17-$A25))/k_kitchen,"") -> 121.12155 | D25: =IFERROR(LN(($C$17-$A25)/($E$17-$A25))/k_printernya,"") -> 87.843785
A26: 10 | B26: =IFERROR(LN(($C$17-$A26)/($E$17-$A26))/k_bedroom,"") -> 116.55524 | C26: =IFERROR(LN(($C$17-$A26)/($E$17-$A26))/k_kitchen,"") -> 183.06804 | D26: =IFERROR(LN(($C$17-$A26)/($E$17-$A26))/k_printernya,"") -> 132.77067
